<?xml version="1.0"?>
<robot name="sendbooster_agv"
  xmlns:xacro="http://ros.org/wiki/xacro">

  <!-- Material definitions -->
  <material name="black">
    <color rgba="0.0 0.0 0.0 1.0"/>
  </material>
  <material name="dark">
    <color rgba="0.3 0.3 0.3 1.0"/>
  </material>
  <material name="light_black">
    <color rgba="0.4 0.4 0.4 1.0"/>
  </material>

  <!-- Base footprint -->
  <link name="base_footprint"/>

  <joint name="base_joint" type="fixed">
    <parent link="base_footprint"/>
    <child link="base_link"/>
    <origin xyz="0 0 0.11725" rpy="0 0 0"/>
  </joint>

  <!-- Base link -->
  <link name="base_link">
    <visual>
      <origin xyz="0 0 0.11725" rpy="1.57 0 0"/>
      <geometry>
        <mesh filename="package://sendbooster_agv_simulation/models/model_stl/meshes/bases/sendbooster_agv_base.stl" scale="0.001 0.001 0.001"/>
      </geometry>
      <material name="light_black"/>
    </visual>

    <collision>
      <origin xyz="0 0 0.11725" rpy="0 0 0"/>
      <geometry>
        <box size="0.6 0.6 0.3"/>
      </geometry>
    </collision>
  </link>

  <!-- Left wheel -->
  <joint name="wheel_left_joint" type="continuous">
    <parent link="base_link"/>
    <child link="wheel_left_link"/>
    <origin xyz="0 0.16 0.09330" rpy="1.57 0 0"/>
    <axis xyz="0 0 1"/>
  </joint>

  <link name="wheel_left_link">
    <visual>
      <origin xyz="0 0 0" rpy="0 0 0"/>
      <geometry>
                <cylinder radius="0.0965" length="0.048"/>
      </geometry>
      <material name="dark"/>
    </visual>

    <collision>
      <origin xyz="0 0 0" rpy="0 0 0"/>
      <geometry>
        <cylinder radius="0.0965" length="0.048"/>
      </geometry>
    </collision>
  </link>

  <!-- Right wheel -->
  <joint name="wheel_right_joint" type="continuous">
    <parent link="base_link"/>
    <child link="wheel_right_link"/>
    <origin xyz="0 -0.16 0.09330" rpy="-1.57 0 0"/>
    <axis xyz="0 0 1"/>
  </joint>

  <link name="wheel_right_link">
    <visual>
      <origin xyz="0 0 0" rpy="0 0 0"/>
      <geometry>
                <cylinder radius="0.0965" length="0.048"/>
      </geometry>
      <material name="dark"/>
    </visual>

    <collision>
      <origin xyz="0 0 0" rpy="0 0 0"/>
      <geometry>
        <cylinder radius="0.0965" length="0.048"/>
      </geometry>
    </collision>
  </link>

  <!-- IMU -->
  <joint name="imu_joint" type="fixed">
    <parent link="base_link"/>
    <child link="imu_link"/>
    <origin xyz="0 0 0.1" rpy="0 0 0"/>
  </joint>

  <link name="imu_link"/>

  <!-- Front Lidar (RPLIDAR A2M8) -->
  <joint name="lidar_joint" type="fixed">
    <parent link="base_link"/>
    <child link="base_scan"/>
    <origin xyz="0.32 0 0" rpy="0 0 0"/>
  </joint>

  <link name="base_scan">
    <visual>
      <origin xyz="0 0 0" rpy="0 0 0"/>
      <geometry>
        <cylinder radius="0.0508" length="0.055"/>
      </geometry>
      <material name="dark"/>
    </visual>

    <collision>
      <origin xyz="0 0 0" rpy="0 0 0"/>
      <geometry>
        <cylinder radius="0.0508" length="0.055"/>
      </geometry>
    </collision>
  </link>

  <!-- Back Lidar (RPLIDAR A2M8) - rotated 180° to face backward -->
  <joint name="lidar_joint_back" type="fixed">
    <parent link="base_link"/>
    <child link="base_scan_back"/>
    <origin xyz="-0.32 0 0" rpy="0 0 3.14159"/>
  </joint>

  <link name="base_scan_back">
    <visual>
      <origin xyz="0 0 0" rpy="0 0 0"/>
      <geometry>
        <cylinder radius="0.0508" length="0.055"/>
      </geometry>
      <material name="dark"/>
    </visual>

    <collision>
      <origin xyz="0 0 0" rpy="0 0 0"/>
      <geometry>
        <cylinder radius="0.0508" length="0.055"/>
      </geometry>
    </collision>
  </link>

</robot>
